Workbook

Sheet Dashboard
B2: Giolitti 48 · Dashboard
B3: Si aggiorna da sola dal foglio Lista: contano solo le righe con ✔. Le celle gialle (budget, margine) sono da compilare.
B5: TOTALE SCELTO | C5: GIÀ PAGATO | E5: ORDINATO | G5: IN PREVENTIVO | I5: DA PAGARE
B6: =SUMIFS(Lista!$J:$J,Lista!$A:$A,"✔") -> 57773 | C6: =SUMIFS(Lista!$J:$J,Lista!$A:$A,"✔",Lista!$K:$K,"Pagato")+SUMIFS(Lista!$J:$J,Lista!$A:$A,"✔",Lista!$K:$K,"Consegnato") -> 20676 | E6: =SUMIFS(Lista!$J:$J,Lista!$A:$A,"✔",Lista!$K:$K,"Ordinato") -> 34749 | G6: =SUMIFS(Lista!$J:$J,Lista!$A:$A,"✔",Lista!$K:$K,"Preventivo") -> 2348 | I6: =B6-C6 -> 37097
B7: =TEXT(COUNTIFS(Lista!$A:$A,"✔"),"0")&" voci scelte" -> 45 voci scelte | C7: =IF(B6=0,"",TEXT(C6/B6,"0%")&" del totale") -> 36% del totale | E7: ="da saldare" -> da saldare | G7: ="da confermare" -> da confermare | I7: ="restano da saldare" -> restano da saldare
B9: Margine imprevisti | C9: 0.1 | D9: Totale con imprevisti | F9: =B6*(1+C9) -> 63550.3
B10: Per categoria
B11: Categoria | C11: Pagato | D11: Ordinato | E11: Preventivo | F11: Scelto, da valutare | G11: Totale | H11: Budget | I11: Residuo | J11: % pagato
B12: Grandi elettrodomestici | C12: =SUMIFS(Lista!$J:$J,Lista!$A:$A,"✔",Lista!$K:$K,"Pagato",Lista!$B:$B,$B12)+SUMIFS(Lista!$J:$J,Lista!$A:$A,"✔",Lista!$K:$K,"Consegnato",Lista!$B:$B,$B12) -> 306 | D12: =SUMIFS(Lista!$J:$J,Lista!$A:$A,"✔",Lista!$K:$K,"Ordinato",Lista!$B:$B,$B12) -> 0 | E12: =SUMIFS(Lista!$J:$J,Lista!$A:$A,"✔",Lista!$K:$K,"Preventivo",Lista!$B:$B,$B12) -> 2348 | F12: =SUMIFS(Lista!$J:$J,Lista!$A:$A,"✔",Lista!$K:$K,"Da valutare",Lista!$B:$B,$B12)+SUMIFS(Lista!$J:$J,Lista!$A:$A,"✔",Lista!$B:$B,$B12,Lista!$K:$K,"") -> 0 | G12: =SUM(C12:F12) -> 2654 | I12: =IF(H12="","",H12-G12) | J12: =IF(G12=0,"",C12/G12) -> 0.11529766
B13: TV & multimedia | C13: =SUMIFS(Lista!$J:$J,Lista!$A:$A,"✔",Lista!$K:$K,"Pagato",Lista!$B:$B,$B13)+SUMIFS(Lista!$J:$J,Lista!$A:$A,"✔",Lista!$K:$K,"Consegnato",Lista!$B:$B,$B13) -> 0 | D13: =SUMIFS(Lista!$J:$J,Lista!$A:$A,"✔",Lista!$K:$K,"Ordinato",Lista!$B:$B,$B13) -> 0 | E13: =SUMIFS(Lista!$J:$J,Lista!$A:$A,"✔",Lista!$K:$K,"Preventivo",Lista!$B:$B,$B13) -> 0 | F13: =SUMIFS(Lista!$J:$J,Lista!$A:$A,"✔",Lista!$K:$K,"Da valutare",Lista!$B:$B,$B13)+SUMIFS(Lista!$J:$J,Lista!$A:$A,"✔",Lista!$B:$B,$B13,Lista!$K:$K,"") -> 0 | G13: =SUM(C13:F13) -> 0 | I13: =IF(H13="","",H13-G13) | J13: =IF(G13=0,"",C13/G13)
B14: Impianto elettrico & domotica | C14: =SUMIFS(Lista!$J:$J,Lista!$A:$A,"✔",Lista!$K:$K,"Pagato",Lista!$B:$B,$B14)+SUMIFS(Lista!$J:$J,Lista!$A:$A,"✔",Lista!$K:$K,"Consegnato",Lista!$B:$B,$B14) -> 0 | D14: =SUMIFS(Lista!$J:$J,Lista!$A:$A,"✔",Lista!$K:$K,"Ordinato",Lista!$B:$B,$B14) -> 0 | E14: =SUMIFS(Lista!$J:$J,Lista!$A:$A,"✔",Lista!$K:$K,"Preventivo",Lista!$B:$B,$B14) -> 0 | F14: =SUMIFS(Lista!$J:$J,Lista!$A:$A,"✔",Lista!$K:$K,"Da valutare",Lista!$B:$B,$B14)+SUMIFS(Lista!$J:$J,Lista!$A:$A,"✔",Lista!$B:$B,$B14,Lista!$K:$K,"") -> 0 | G14: =SUM(C14:F14) -> 0 | I14: =IF(H14="","",H14-G14) | J14: =IF(G14=0,"",C14/G14)
B15: Illuminazione | C15: =SUMIFS(Lista!$J:$J,Lista!$A:$A,"✔",Lista!$K:$K,"Pagato",Lista!$B:$B,$B15)+SUMIFS(Lista!$J:$J,Lista!$A:$A,"✔",Lista!$K:$K,"Consegnato",Lista!$B:$B,$B15) -> 310 | D15: =SUMIFS(Lista!$J:$J,Lista!$A:$A,"✔",Lista!$K:$K,"Ordinato",Lista!$B:$B,$B15) -> 0 | E15: =SUMIFS(Lista!$J:$J,Lista!$A:$A,"✔",Lista!$K:$K,"Preventivo",Lista!$B:$B,$B15) -> 0 | F15: =SUMIFS(Lista!$J:$J,Lista!$A:$A,"✔",Lista!$K:$K,"Da valutare",Lista!$B:$B,$B15)+SUMIFS(Lista!$J:$J,Lista!$A:$A,"✔",Lista!$B:$B,$B15,Lista!$K:$K,"") -> 0 | G15: =SUM(C15:F15) -> 310 | I15: =IF(H15="","",H15-G15) | J15: =IF(G15=0,"",C15/G15) -> 1
B16: Clima & comfort | C16: =SUMIFS(Lista!$J:$J,Lista!$A:$A,"✔",Lista!$K:$K,"Pagato",Lista!$B:$B,$B16)+SUMIFS(Lista!$J:$J,Lista!$A:$A,"✔",Lista!$K:$K,"Consegnato",Lista!$B:$B,$B16) -> 0 | D16: =SUMIFS(Lista!$J:$J,Lista!$A:$A,"✔",Lista!$K:$K,"Ordinato",Lista!$B:$B,$B16) -> 0 | E16: =SUMIFS(Lista!$J:$J,Lista!$A:$A,"✔",Lista!$K:$K,"Preventivo",Lista!$B:$B,$B16) -> 0 | F16: =SUMIFS(Lista!$J:$J,Lista!$A:$A,"✔",Lista!$K:$K,"Da valutare",Lista!$B:$B,$B16)+SUMIFS(Lista!$J:$J,Lista!$A:$A,"✔",Lista!$B:$B,$B16,Lista!$K:$K,"") -> 0 | G16: =SUM(C16:F16) -> 0 | I16: =IF(H16="","",H16-G16) | J16: =IF(G16=0,"",C16/G16)
B17: Bagno | C17: =SUMIFS(Lista!$J:$J,Lista!$A:$A,"✔",Lista!$K:$K,"Pagato",Lista!$B:$B,$B17)+SUMIFS(Lista!$J:$J,Lista!$A:$A,"✔",Lista!$K:$K,"Consegnato",Lista!$B:$B,$B17) -> 0 | D17: =SUMIFS(Lista!$J:$J,Lista!$A:$A,"✔",Lista!$K:$K,"Ordinato",Lista!$B:$B,$B17) -> 32000 | E17: =SUMIFS(Lista!$J:$J,Lista!$A:$A,"✔",Lista!$K:$K,"Preventivo",Lista!$B:$B,$B17) -> 0 | F17: =SUMIFS(Lista!$J:$J,Lista!$A:$A,"✔",Lista!$K:$K,"Da valutare",Lista!$B:$B,$B17)+SUMIFS(Lista!$J:$J,Lista!$A:$A,"✔",Lista!$B:$B,$B17,Lista!$K:$K,"") -> 0 | G17: =SUM(C17:F17) -> 32000 | I17: =IF(H17="","",H17-G17) | J17: =IF(G17=0,"",C17/G17) -> 0 | L17: 32.000€ sia bagno adele affitto che piano 2. / altri 11.000€ bagno mansarda
B18: Cucina: arredo & accessori | C18: =SUMIFS(Lista!$J:$J,Lista!$A:$A,"✔",Lista!$K:$K,"Pagato",Lista!$B:$B,$B18)+SUMIFS(Lista!$J:$J,Lista!$A:$A,"✔",Lista!$K:$K,"Consegnato",Lista!$B:$B,$B18) -> 20060 | D18: =SUMIFS(Lista!$J:$J,Lista!$A:$A,"✔",Lista!$K:$K,"Ordinato",Lista!$B:$B,$B18) -> 0 | E18: =SUMIFS(Lista!$J:$J,Lista!$A:$A,"✔",Lista!$K:$K,"Preventivo",Lista!$B:$B,$B18) -> 0 | F18: =SUMIFS(Lista!$J:$J,Lista!$A:$A,"✔",Lista!$K:$K,"Da valutare",Lista!$B:$B,$B18)+SUMIFS(Lista!$J:$J,Lista!$A:$A,"✔",Lista!$B:$B,$B18,Lista!$K:$K,"") -> 0 | G18: =SUM(C18:F18) -> 20060 | I18: =IF(H18="","",H18-G18) | J18: =IF(G18=0,"",C18/G18) -> 1
B19: Piccoli elettrodomestici | C19: =SUMIFS(Lista!$J:$J,Lista!$A:$A,"✔",Lista!$K:$K,"Pagato",Lista!$B:$B,$B19)+SUMIFS(Lista!$J:$J,Lista!$A:$A,"✔",Lista!$K:$K,"Consegnato",Lista!$B:$B,$B19) -> 0 | D19: =SUMIFS(Lista!$J:$J,Lista!$A:$A,"✔",Lista!$K:$K,"Ordinato",Lista!$B:$B,$B19) -> 0 | E19: =SUMIFS(Lista!$J:$J,Lista!$A:$A,"✔",Lista!$K:$K,"Preventivo",Lista!$B:$B,$B19) -> 0 | F19: =SUMIFS(Lista!$J:$J,Lista!$A:$A,"✔",Lista!$K:$K,"Da valutare",Lista!$B:$B,$B19)+SUMIFS(Lista!$J:$J,Lista!$A:$A,"✔",Lista!$B:$B,$B19,Lista!$K:$K,"") -> 0 | G19: =SUM(C19:F19) -> 0 | I19: =IF(H19="","",H19-G19) | J19: =IF(G19=0,"",C19/G19)
B20: Finiture & serramenti | C20: =SUMIFS(Lista!$J:$J,Lista!$A:$A,"✔",Lista!$K:$K,"Pagato",Lista!$B:$B,$B20)+SUMIFS(Lista!$J:$J,Lista!$A:$A,"✔",Lista!$K:$K,"Consegnato",Lista!$B:$B,$B20) -> 0 | D20: =SUMIFS(Lista!$J:$J,Lista!$A:$A,"✔",Lista!$K:$K,"Ordinato",Lista!$B:$B,$B20) -> 0 | E20: =SUMIFS(Lista!$J:$J,Lista!$A:$A,"✔",Lista!$K:$K,"Preventivo",Lista!$B:$B,$B20) -> 0 | F20: =SUMIFS(Lista!$J:$J,Lista!$A:$A,"✔",Lista!$K:$K,"Da valutare",Lista!$B:$B,$B20)+SUMIFS(Lista!$J:$J,Lista!$A:$A,"✔",Lista!$B:$B,$B20,Lista!$K:$K,"") -> 0 | G20: =SUM(C20:F20) -> 0 | I20: =IF(H20="","",H20-G20) | J20: =IF(G20=0,"",C20/G20)
B21: Soggiorno | C21: =SUMIFS(Lista!$J:$J,Lista!$A:$A,"✔",Lista!$K:$K,"Pagato",Lista!$B:$B,$B21)+SUMIFS(Lista!$J:$J,Lista!$A:$A,"✔",Lista!$K:$K,"Consegnato",Lista!$B:$B,$B21) -> 0 | D21: =SUMIFS(Lista!$J:$J,Lista!$A:$A,"✔",Lista!$K:$K,"Ordinato",Lista!$B:$B,$B21) -> 2749 | E21: =SUMIFS(Lista!$J:$J,Lista!$A:$A,"✔",Lista!$K:$K,"Preventivo",Lista!$B:$B,$B21) -> 0 | F21: =SUMIFS(Lista!$J:$J,Lista!$A:$A,"✔",Lista!$K:$K,"Da valutare",Lista!$B:$B,$B21)+SUMIFS(Lista!$J:$J,Lista!$A:$A,"✔",Lista!$B:$B,$B21,Lista!$K:$K,"") -> 0 | G21: =SUM(C21:F21) -> 2749 | I21: =IF(H21="","",H21-G21) | J21: =IF(G21=0,"",C21/G21) -> 0
B22: Camera da letto | C22: =SUMIFS(Lista!$J:$J,Lista!$A:$A,"✔",Lista!$K:$K,"Pagato",Lista!$B:$B,$B22)+SUMIFS(Lista!$J:$J,Lista!$A:$A,"✔",Lista!$K:$K,"Consegnato",Lista!$B:$B,$B22) -> 0 | D22: =SUMIFS(Lista!$J:$J,Lista!$A:$A,"✔",Lista!$K:$K,"Ordinato",Lista!$B:$B,$B22) -> 0 | E22: =SUMIFS(Lista!$J:$J,Lista!$A:$A,"✔",Lista!$K:$K,"Preventivo",Lista!$B:$B,$B22) -> 0 | F22: =SUMIFS(Lista!$J:$J,Lista!$A:$A,"✔",Lista!$K:$K,"Da valutare",Lista!$B:$B,$B22)+SUMIFS(Lista!$J:$J,Lista!$A:$A,"✔",Lista!$B:$B,$B22,Lista!$K:$K,"") -> 0 | G22: =SUM(C22:F22) -> 0 | I22: =IF(H22="","",H22-G22) | J22: =IF(G22=0,"",C22/G22)
B23: Tende & tessili | C23: =SUMIFS(Lista!$J:$J,Lista!$A:$A,"✔",Lista!$K:$K,"Pagato",Lista!$B:$B,$B23)+SUMIFS(Lista!$J:$J,Lista!$A:$A,"✔",Lista!$K:$K,"Consegnato",Lista!$B:$B,$B23) -> 0 | D23: =SUMIFS(Lista!$J:$J,Lista!$A:$A,"✔",Lista!$K:$K,"Ordinato",Lista!$B:$B,$B23) -> 0 | E23: =SUMIFS(Lista!$J:$J,Lista!$A:$A,"✔",Lista!$K:$K,"Preventivo",Lista!$B:$B,$B23) -> 0 | F23: =SUMIFS(Lista!$J:$J,Lista!$A:$A,"✔",Lista!$K:$K,"Da valutare",Lista!$B:$B,$B23)+SUMIFS(Lista!$J:$J,Lista!$A:$A,"✔",Lista!$B:$B,$B23,Lista!$K:$K,"") -> 0 | G23: =SUM(C23:F23) -> 0 | I23: =IF(H23="","",H23-G23) | J23: =IF(G23=0,"",C23/G23)
B24: Studio | C24: =SUMIFS(Lista!$J:$J,Lista!$A:$A,"✔",Lista!$K:$K,"Pagato",Lista!$B:$B,$B24)+SUMIFS(Lista!$J:$J,Lista!$A:$A,"✔",Lista!$K:$K,"Consegnato",Lista!$B:$B,$B24) -> 0 | D24: =SUMIFS(Lista!$J:$J,Lista!$A:$A,"✔",Lista!$K:$K,"Ordinato",Lista!$B:$B,$B24) -> 0 | E24: =SUMIFS(Lista!$J:$J,Lista!$A:$A,"✔",Lista!$K:$K,"Preventivo",Lista!$B:$B,$B24) -> 0 | F24: =SUMIFS(Lista!$J:$J,Lista!$A:$A,"✔",Lista!$K:$K,"Da valutare",Lista!$B:$B,$B24)+SUMIFS(Lista!$J:$J,Lista!$A:$A,"✔",Lista!$B:$B,$B24,Lista!$K:$K,"") -> 0 | G24: =SUM(C24:F24) -> 0 | I24: =IF(H24="","",H24-G24) | J24: =IF(G24=0,"",C24/G24)
B25: Ingresso, ripostiglio & lavanderia | C25: =SUMIFS(Lista!$J:$J,Lista!$A:$A,"✔",Lista!$K:$K,"Pagato",Lista!$B:$B,$B25)+SUMIFS(Lista!$J:$J,Lista!$A:$A,"✔",Lista!$K:$K,"Consegnato",Lista!$B:$B,$B25) -> 0 | D25: =SUMIFS(Lista!$J:$J,Lista!$A:$A,"✔",Lista!$K:$K,"Ordinato",Lista!$B:$B,$B25) -> 0 | E25: =SUMIFS(Lista!$J:$J,Lista!$A:$A,"✔",Lista!$K:$K,"Preventivo",Lista!$B:$B,$B25) -> 0 | F25: =SUMIFS(Lista!$J:$J,Lista!$A:$A,"✔",Lista!$K:$K,"Da valutare",Lista!$B:$B,$B25)+SUMIFS(Lista!$J:$J,Lista!$A:$A,"✔",Lista!$B:$B,$B25,Lista!$K:$K,"") -> 0 | G25: =SUM(C25:F25) -> 0 | I25: =IF(H25="","",H25-G25) | J25: =IF(G25=0,"",C25/G25)
B26: Sicurezza & varie | C26: =SUMIFS(Lista!$J:$J,Lista!$A:$A,"✔",Lista!$K:$K,"Pagato",Lista!$B:$B,$B26)+SUMIFS(Lista!$J:$J,Lista!$A:$A,"✔",Lista!$K:$K,"Consegnato",Lista!$B:$B,$B26) -> 0 | D26: =SUMIFS(Lista!$J:$J,Lista!$A:$A,"✔",Lista!$K:$K,"Ordinato",Lista!$B:$B,$B26) -> 0 | E26: =SUMIFS(Lista!$J:$J,Lista!$A:$A,"✔",Lista!$K:$K,"Preventivo",Lista!$B:$B,$B26) -> 0 | F26: =SUMIFS(Lista!$J:$J,Lista!$A:$A,"✔",Lista!$K:$K,"Da valutare",Lista!$B:$B,$B26)+SUMIFS(Lista!$J:$J,Lista!$A:$A,"✔",Lista!$B:$B,$B26,Lista!$K:$K,"") -> 0 | G26: =SUM(C26:F26) -> 0 | I26: =IF(H26="","",H26-G26) | J26: =IF(G26=0,"",C26/G26)
B27: Servizi & trasloco | C27: =SUMIFS(Lista!$J:$J,Lista!$A:$A,"✔",Lista!$K:$K,"Pagato",Lista!$B:$B,$B27)+SUMIFS(Lista!$J:$J,Lista!$A:$A,"✔",Lista!$K:$K,"Consegnato",Lista!$B:$B,$B27) -> 0 | D27: =SUMIFS(Lista!$J:$J,Lista!$A:$A,"✔",Lista!$K:$K,"Ordinato",Lista!$B:$B,$B27) -> 0 | E27: =SUMIFS(Lista!$J:$J,Lista!$A:$A,"✔",Lista!$K:$K,"Preventivo",Lista!$B:$B,$B27) -> 0 | F27: =SUMIFS(Lista!$J:$J,Lista!$A:$A,"✔",Lista!$K:$K,"Da valutare",Lista!$B:$B,$B27)+SUMIFS(Lista!$J:$J,Lista!$A:$A,"✔",Lista!$B:$B,$B27,Lista!$K:$K,"") -> 0 | G27: =SUM(C27:F27) -> 0 | I27: =IF(H27="","",H27-G27) | J27: =IF(G27=0,"",C27/G27)
B28: TOTALE | C28: =SUM(C12:C27) -> 20676 | D28: =SUM(D12:D27) -> 34749 | E28: =SUM(E12:E27) -> 2348 | F28: =SUM(F12:F27) -> 0 | G28: =SUM(G12:G27) -> 57773 | H28: =SUM(H12:H27) -> 0 | I28: =IF(H28=0,"",H28-G28) | J28: =IF(G28=0,"",C28/G28) -> 0.35788344
B30: Stato dei soldi
B31: Pagato | C31: =C6 -> 20676 | D31: =IF($B$6=0,"",C31/$B$6) -> 0.35788344
B32: Ordinato | C32: =E6 -> 34749 | D32: =IF($B$6=0,"",C32/$B$6) -> 0.60147474
B33: In preventivo | C33: =G6 -> 2348 | D33: =IF($B$6=0,"",C33/$B$6) -> 0.040641822
B34: Scelto, da valutare | C34: =F28 -> 0 | D34: =IF($B$6=0,"",C34/$B$6) -> 0

Sheet Lista
A1: BUYING · Via Giolitti 48
A2: Scrivi nelle colonne bianche. Metti ✔ nella prima colonna per far contare la riga nella Dashboard. Per aggiungere una voce scrivi nella prima riga vuota in fondo: la tabella si allarga da sola.
A4: ✔ | B4: Categoria | C4: Voce | D4: Opz. | E4: Brand | F4: Modello | G4: Misure | H4: Q.tà | I4: Prezzo € | J4: Totale € | K4: Stato | L4: Stanza | M4: Negozio / link / sconti | N4: Note | O4: Quando | P4: Bonus mobili
A5: ✔ | B5: Grandi elettrodomestici | C5: Frigorifero | E5: Electrolux | F5: KNA7CD18S | H5: 1 | I5: 0 | J5: =N(H5)*N(I5) -> 0 | K5: Pagato | L5: Cucina | O5: Prima delle tracce | P5: Sì
A6: ✔ | B6: Grandi elettrodomestici | C6: Lavastoviglie | E6: Electrolux | F6: KL72A202S | H6: 1 | I6: 0 | J6: =N(H6)*N(I6) -> 0 | K6: Pagato | L6: Cucina | O6: Prima delle tracce | P6: Sì
A7: ✔ | B7: Grandi elettrodomestici | C7: Forno | E7: Electrolux | F7: KOFCH20H | H7: 1 | J7: =N(H7)*N(I7) -> 0 | K7: Pagato | L7: Cucina | O7: Prima delle tracce | P7: Sì
A8: ✔ | B8: Grandi elettrodomestici | C8: Microonde | E8: Electrolux | F8: KMSD254TBH | G8: Incassato sopra forno | H8: 1 | J8: =N(H8)*N(I8) -> 0 | K8: Pagato | L8: Cucina | O8: Prima delle tracce | P8: Sì
A9: ✔ | B9: Grandi elettrodomestici | C9: Piano a induzione | E9: Electrolux | F9: KCC83410CK | H9: 1 | J9: =N(H9)*N(I9) -> 0 | K9: Pagato | L9: Cucina | O9: Prima delle tracce | P9: Sì
A10: ✔ | B10: Grandi elettrodomestici | C10: Cappa | E10: Electrolux | F10: KCC83410CK_ integrata nel piano induzione | H10: 1 | J10: =N(H10)*N(I10) -> 0 | K10: Pagato | L10: Cucina | N10: Cappa filtrante a ricircolo | O10: Prima delle tracce | P10: Sì
A11: ✔ | B11: Grandi elettrodomestici | C11: Lavatrice | E11: Miele | F11: WWB360WCS | H11: 1 | I11: 1099 | J11: =N(H11)*N(I11) -> 1099 | K11: Preventivo | L11: Lavanderia | M11: sconto lux = 100€ | O11: Prima delle tracce | P11: Sì
A12: ✔ | B12: Grandi elettrodomestici | C12: Asciugatrice | E12: Miele | F12: TWC640WP | H12: 1 | I12: 1249 | J12: =N(H12)*N(I12) -> 1249 | K12: Preventivo | L12: Lavanderia | M12: Sconto lux = 124€ | N12: In colonna serve il kit di sovrapposizione. | O12: Prima delle tracce | P12: Sì
A13: ✔ | B13: Grandi elettrodomestici | C13: Cantinetta vino | E13: CANDY | F13: VINO - DI VINO CCVB 30/1 | H13: 1 | I13: 306 | J13: 306 | K13: Pagato | L13: Cucina | M13: Sconto lux = 100€ | N13: Prezzo iniziale 549€, poi sconto Lux (numero ordine online: IT032536) | O13: Fine lavori | P13: Sì
B14: TV & multimedia | C14: TV soggiorno | D14: A | E14: LG OLED AI B6E 55 | F14: OLED55B6ELC | G14: 55" · | H14: 1 | I14: 999 | J14: =N(H14)*N(I14) -> 999 | K14: Da valutare | L14: Soggiorno | N14: Altezza e posizione vanno decise prima dei lavori: presa, antenna e canalina per i cavi nel muro. | O14: Fine lavori | P14: No
B15: TV & multimedia | C15: TV soggiorno | D15: B | E15: LG OLED AI B6 Pro 55 | F15: OLED55B65LA | G15: 55" · | H15: 1 | I15: 1099 | J15: =N(H15)*N(I15)*0.83 -> 912.17 | K15: Da valutare | L15: Soggiorno | N15: Sconto luxottica da 1099€ a 912€ | O15: Fine lavori | P15: No
B16: TV & multimedia | C16: TV soggiorno | D16: C | H16: 1 | I16: 1150 | J16: =N(H16)*N(I16) -> 1150 | K16: Da valutare | L16: Soggiorno | O16: Fine lavori | P16: No
B17: TV & multimedia | C17: TV camera o monitor | H17: 1 | J17: =N(H17)*N(I17) -> 0 | K17: Da valutare | L17: Camera | O17: Fine lavori | P17: No
B18: TV & multimedia | C18: Staffa TV a muro | H18: 1 | J18: =N(H18)*N(I18) -> 0 | K18: Da valutare | L18: Soggiorno | N18: Verifica lo standard VESA della TV scelta. | O18: Fine lavori | P18: No
B19: TV & multimedia | C19: Router / Wi-Fi mesh | H19: 1 | J19: =N(H19)*N(I19) -> 0 | K19: Da valutare | L19: Casa | N19: Posizione centrale; porta la fibra dove serve. | O19: Prima delle tracce | P19: No
B20: TV & multimedia | C20: Cavi HDMI, prolunghe, multiprese | H20: 1 | J20: =N(H20)*N(I20) -> 0 | K20: Da valutare | L20: Casa | O20: Dopo trasloco | P20: No
B21: Impianto elettrico & domotica | C21: Serie civile: placche e frutti | H21: 1 | J21: =N(H21)*N(I21) -> 0 | K21: Da valutare | L21: Casa | O21: Prima delle tracce | P21: No
B22: Impianto elettrico & domotica | C22: Prese Schuko / bipasso | H22: 20 | J22: =N(H22)*N(I22) -> 0 | K22: Da valutare | L22: Casa | O22: Prima delle tracce | P22: No
B23: Impianto elettrico & domotica | C23: Prese USB-A / USB-C | H23: 6 | J23: =N(H23)*N(I23) -> 0 | K23: Da valutare | L23: Casa | N23: Comodini, scrivania, cucina. | O23: Prima delle tracce | P23: No
B24: Impianto elettrico & domotica | C24: Interruttori / deviatori | H24: 14 | J24: =N(H24)*N(I24) -> 0 | K24: Da valutare | L24: Casa | O24: Prima delle tracce | P24: No
B25: Impianto elettrico & domotica | C25: Prese TV / SAT | H25: 3 | J25: =N(H25)*N(I25) -> 0 | K25: Da valutare | L25: Casa | O25: Prima delle tracce | P25: No
B26: Impianto elettrico & domotica | C26: Prese dati RJ45 | H26: 4 | J26: =N(H26)*N(I26) -> 0 | K26: Da valutare | L26: Casa | O26: Prima delle tracce | P26: No
B27: Impianto elettrico & domotica | C27: Prese dedicate elettrodomestici | H27: 6 | J27: =N(H27)*N(I27) -> 0 | K27: Da valutare | L27: Cucina | O27: Prima delle tracce | P27: No
B28: Impianto elettrico & domotica | C28: Termostato smart | H28: 1 | J28: =N(H28)*N(I28) -> 0 | K28: Da valutare | L28: Casa | O28: Prima delle tracce | P28: No
B29: Impianto elettrico & domotica | C29: Allarme (Verisure o SecureItalia) | H29: 1 | J29: =N(H29)*N(I29) -> 0 | K29: Da valutare | L29: Casa | O29: Prima delle tracce | P29: No
B30: Impianto elettrico & domotica | C30: Rilevatori fumo / gas / allagamento | H30: 3 | J30: =N(H30)*N(I30) -> 0 | K30: Da valutare | L30: Casa | O30: Prima delle tracce | P30: No
B31: Illuminazione | C31: Faretti da incasso | H31: 12 | J31: =N(H31)*N(I31) -> 0 | K31: Da valutare | L31: Ingresso + sgabuzzino + cabina armadio | O31: Prima delle tracce | P31: Sì
B32: Illuminazione | C32: Strisce LED con profili | H32: 1 | J32: =N(H32)*N(I32) -> 0 | K32: Da valutare | L32: Cucina | O32: Prima delle tracce | P32: Sì
B33: Illuminazione | C33: Piantana / Snoopy flos | H33: 1 | J33: =N(H33)*N(I33) -> 0 | K33: Da valutare | L33: Cucina | O33: Fine lavori | P33: Sì
B34: Illuminazione | C34: Luce specchio bagno | H34: 1 | J34: =N(H34)*N(I34) -> 0 | K34: Da valutare | L34: Bagno | O34: Fine lavori | P34: Sì
A35: ✔ | B35: Illuminazione | C35: Applique soffitto bagno | E35: Flos | F35: Ariette | H35: 1 | I35: 310 | J35: =N(H35)*N(I35) -> 310 | K35: Pagato | L35: Bagno | O35: Fine lavori | P35: Sì
B36: Illuminazione | C36: Applique muri | H36: 3 | J36: =N(H36)*N(I36) -> 0 | K36: Da valutare | L36: Cucina | O36: Fine lavori | P36: Sì
B37: Illuminazione | C37: Lampade da comodino | H37: 2 | J37: =N(H37)*N(I37) -> 0 | K37: Da valutare | L37: Camera | O37: Dopo trasloco | P37: Sì
B38: Illuminazione | C38: Applique balcone | H38: 2 | J38: =N(H38)*N(I38) -> 0 | K38: Da valutare | L38: Esterno | O38: Fine lavori | P38: Sì
B39: Illuminazione | C39: Luci armadio con sensore | H39: 1 | J39: =N(H39)*N(I39) -> 0 | K39: Da valutare | L39: Camera | O39: Fine lavori | P39: Sì
B40: Illuminazione | C40: Lampadine | H40: 10 | J40: =N(H40)*N(I40) -> 0 | K40: Da valutare | L40: Casa | O40: Dopo trasloco | P40: No
A41: ✔ | B41: Clima & comfort | C41: Climatizzatore | H41: 1 | I41: 0 | J41: =N(H41)*N(I41) -> 0 | K41: Ordinato | L41: Soggiorno | O41: Prima delle tracce | P41: Sì
...

Sheet idee comodini
A1: SKLUM
A2: COMODINO
A3: https://www.sklum.com/it/acquistare-comodino/233303-comodino-ovale-50x35-cm-in-acciaio-inox-luena.html?id_c=717031
A4: MOBILE TV
A5: https://www.sklum.com/it/acquistare-credenza/224573-aparador-160x40-cm-in-acciaio-inossidabile-luena.html?id_c=665055&_gl=1*1x5n3ok*_up*MQ..*_ga*MTIzNDcwODM1LjE3OTA2ODgzOTk.*_ga_Z2482RZ0GH*czE3OTA2ODgzOTgkbzEkZzAkdDE3OTA2ODgzOTgkajYwJGwwJGg5Mzg3MzEyMTg.

Sheet dettagli cucina

Sheet Svendite
A1: Nome | B1: Data | C1: Luogo | D1: Orario | E1: Note
A2: FLOS | B2: 09/10 - 11/10 | C2: Via A. Faini 2 Bovezzo | D2: dalle 9.30 alle 19 | E2: Family & Friends Flos - QR CODE (Mail 22 settembre)
A3: SAMBONET / ROSENTHAL | B3: 46310 | C3: Via Gardone 9 | D3: 19 | E3: Mail SampleLover
A4: ARTEMIDE | B4: 15/10 - 18/10 | C4: Via Bergamo 17 Pregnana Milanese | D4: dalle 9 alle 19 | E4: Artemide: Invio Codice Cliente 10056694
A5: KARTELL | C5: OUTLET - Via delle Industrie 3 - Noviglio | E5: https://www.kartell.com/it/it/ktit/storelocator/store/outlet-kartell-noviglio/kf00075?srsltid=AU7gw4WzGwqSw56TtJbcJc_eODvIBkcXE8JU2PKIbk6NhwVcBchc6WuN
A6: GINORI 1735 | B6: 46301 | C6: Via San Gregorio 39 | D6: dalle 9 alle 20 | E6: Arlettie

Sheet SEDIE

Sheet ILLUMINAZIONE - flos

Sheet ILLUMINAZIONE ARTEMIDE
